<?xml version="1.0"?>

<robot xmlns:xacro="http://playerstage.sourceforge.net/gazebo/xmlschema/#xacro">

  <xacro:macro name="wheel" params="name xyz direction side connected_to='base_link'">

    <link name="${name}_wheel_link">
      <inertial>
        <origin xyz="-0.0002104 5.31e-05 -0.0004148" rpy="0 0 0"/>
        <mass value="0.162"/>
        <inertia ixx="0.0002" ixy="0" ixz="0" iyy="0.00012" iyz="0" izz="0.00012"/>
      </inertial>
      <visual name="${name}_wheel_bolt">
        <origin xyz="0 ${side * 0.0145} 0" rpy="${pi/2} 0 0"/>
        <geometry>
          <cylinder radius="0.007" length="0.001"/>
        </geometry>
        <material name="bolt">
          <color rgba="0.45 0.15 0.0 1.0"/>
        </material>
      </visual>
      <visual name="${name}_wheel">
        <origin xyz="0 0 0" rpy="0 0 0"/>
        <geometry>
          <mesh filename="package://ep_description/meshes/wheel.dae" scale="1.0 ${direction} 1.0"/>
        </geometry>
        <material name="wheel_plastic"/>
      </visual>
      <collision name="${name}_wheel">
        <origin xyz="0 0 0" rpy="${pi/2} 0 0"/>
        <geometry>
          <cylinder radius="0.05" length="0.042"/>
        </geometry>
        <material name="collision">
          <color rgba="0.8 0.0 0.0 1.0"/>
        </material>
      </collision>
    </link>

<!--    <joint name="${name}_wheel_joint" type="continuous">-->
    <joint name="${name}_wheel_joint" type="revolute">
      <origin xyz="${xyz}" rpy="0 0 0"/>
      <parent link="${connected_to}"/>
      <child link="${name}_wheel_link"/>
      <axis xyz="0 1.0 0"/>
      <limit effort="3" velocity="76" lower="-1e10" upper="1e10"/>
    </joint>

  </xacro:macro>

  <xacro:macro name="wheel_transmission" params="name mechanical_reduction">
    <transmission name="${name}_wheel_trans">
      <type>transmission_interface/SimpleTransmission</type>
      <actuator name="${name}_wheel_motor">
        <hardwareInterface>hardware_interface/EffortJointInterface</hardwareInterface>
        <mechanicalReduction>${mechanical_reduction}</mechanicalReduction>
      </actuator>
      <joint name="${name}_wheel_joint">
        <hardwareInterface>hardware_interface/EffortJointInterface</hardwareInterface>
      </joint>
    </transmission>
  </xacro:macro>

</robot>
